Workbook

Sheet 1. Household Inputs
A1: FOSH Proof of Concept: Household Input Declaration
A2: This sheet declares all household facts used by both plans. Nothing here changes between Plan A and Plan B.
A3: Blue text = user inputs. Black text = formulas. Green text = cross-sheet links. | D3: Yellow highlight = declared household data.
A4: DEMOGRAPHICS
A5: Item | B5: Spouse 1 | C5: Spouse 2 | D5: Source / Notes
A6: Age | B6: 44 | C6: 42 | D6: Baseline: verified
A7: Filing Status | B7: MFJ | D7: Baseline: verified
A8: State | B8: Colorado | D8: Baseline: verified
A9: Dependents | B9: 2 | D9: Ages 14 and 10
A10: Target Retirement Age | B10: 65 | C10: 65 | D10: Baseline: household-reported
A12: INCOME FLOWS
A13: Item | B13: Annual Amount | C13: Monthly Amount | D13: Source / Notes
A14: Spouse 1 Employment | B14: 110000 | C14: =B14/12 -> 9166.6667 | D14: Document-backed
A15: Spouse 2 Employment | B15: 75000 | C15: =B15/12 -> 6250 | D15: Document-backed
A16: Combined Gross Income | B16: =B14+B15 -> 185000 | C16: =C14+C15 -> 15416.667 | D16: Formula
A18: ASSETS
A19: Account | B19: Balance | C19: Monthly Contrib. | D19: Source / Notes
A20: Spouse 1 401(k) | B20: 185000 | C20: 917 | D20: Document-backed; 6% for match
A21: Spouse 2 401(k) | B21: 92000 | C21: 625 | D21: Document-backed; 10% of salary
A22: Joint Taxable Savings | B22: 28000 | C22: 0 | D22: Document-backed
A23: 529 Plan (Child 1, age 14) | B23: 22000 | C23: 200 | D23: Document-backed
A24: Primary Residence Equity | B24: 195000 | D24: Estimated (Zillow)
A26: LIABILITIES
A27: Debt | B27: Balance | C27: Rate (APR) | D27: Minimum Payment
A28: Auto Loan | B28: 18500 | C28: 0.059 | D28: 373
A29: Student Loan | B29: 31000 | C29: 0.045 | D29: 290
A30: Mortgage | B30: 280000 | C30: 0.0375 | D30: 1297
A32: MONTHLY CASH FLOW
A33: Item | B33: Monthly Amount | D33: Source / Notes
A34: Combined Gross Monthly Income | B34: =C16 -> 15416.667 | D34: Link
A35: Estimated Taxes & FICA (25%) | B35: =ROUND(B34*0.25,0) -> 3854 | D35: Effective rate assumption
A36: Baseline Living Expenses | B36: 6800 | D36: Household-reported (not corroborated)
A37: Existing 401(k) Contributions | B37: =C20+C21 -> 1542 | D37: Link
A38: Existing 529 Contribution | B38: =C23 -> 200 | D38: Link
A39: Minimum Debt Payments | B39: =SUM(D28:D30) -> 1960 | D39: Link
A40: Available Monthly Surplus | B40: =B34-B35-B36-B37-B38-B39 -> 1060.6667 | D40: Residual cash flow
A42: DECLARED MODELING SCOPE
A43: Objective Domain | B43: Status | C43: Evaluable? | D43: Notes
A44: Cashflow Sustainability (Retirement) | B44: Active | C44: Yes | D44: Obj 1: maximize retirement balance at 65
A45: Education Funding | B45: Active | C45: Yes | D45: Obj 2: maximize 529 funding ratio
...

Sheet 2. Plan Comparison
A1: Two Plans for the Same Household: Surplus Allocation
A2: Both plans allocate the same monthly surplus across the same three domains, ensuring that any difference in outcomes reflects allocation strategy, not resource differences.
A3: Blue text denotes that planner's recommended allocations.
A5: Available Monthly Surplus | B5: ='1. Household Inputs'!B40 -> 1060.6667
A7: PLAN A: "Debt-First" Strategy
A8: Allocation Bucket | B8: Monthly $ | C8: % of Surplus | D8: Commitment | E8: Rationale
A9: Extra Auto Loan Payment | B9: 600 | C9: =B9/B5 -> 0.56568196 | D9: Proposed | E9: Highest rate: 5.9% APR
A10: Extra Student Loan Payment | B10: 50 | C10: =B10/B5 -> 0.047140163 | D10: Proposed | E10: Second priority by rate
A11: Additional 529 Contribution | B11: 300 | C11: =B11/B5 -> 0.28284098 | D11: Approved | E11: Close gap to target
A12: Additional 401(k) Contribution | B12: =B5-B9-B10-B11 -> 110.66667 | C12: =B12/B5 -> 0.1043369 | D12: Proposed | E12: Remainder to retirement
A13: Plan A Total | B13: =SUM(B9:B12) -> 1060.6667 | C13: =B13/B5 -> 1
A14: Surplus Check (must = 0) | B14: =B5-B13 -> 0
A16: PLAN B: "Balanced Growth" Strategy
A17: Allocation Bucket | B17: Monthly $ | C17: % of Surplus | D17: Commitment | E17: Rationale
A18: Extra Auto Loan Payment | B18: 100 | C18: =B18/B5 -> 0.094280327 | D18: Proposed | E18: Minimum extra; focus on growth
A19: Extra Student Loan Payment | B19: 100 | C19: =B19/B5 -> 0.094280327 | D19: Proposed | E19: Minimum extra
A20: Additional 529 Contribution | B20: 300 | C20: =B20/B5 -> 0.28284098 | D20: Approved | E20: Close gap to target
A21: Additional 401(k) Contribution | B21: =B5-B18-B19-B20 -> 560.66667 | C21: =B21/B5 -> 0.52859837 | D21: Proposed | E21: Maximize tax-advantaged growth
A22: Plan B Total | B22: =SUM(B18:B21) -> 1060.6667 | C22: =B22/B5 -> 1
A23: Surplus Check (must = 0) | B23: =B5-B22 -> 0

Sheet 3. Objective Functions
A1: Objective Function Computations (Phased Model)
A2: This sheet computes three measurable outcomes for each plan: retirement balance at 65, education funding ratio at enrollment, and total interest paid on debt. These are the three objectives the household has declared. FOSH evaluates plan efficiency across all three simultaneously.
A3: The phased model redirects freed debt payments to the 401(k) after payoff, capturing the system-level interaction between debt and retirement. Objective 3 (interest) is computed first because debt payoff timing determines the redirect streams used in Objective 1.
A5: REFERENCE DATA (linked from Inputs)
A6: Parameter | B6: Value
A7: r_401k: Monthly return on 401(k) | B7: =(1+'1. Household Inputs'!B52)^(1/12)-1 -> 0.0056541454
A8: r_529: Monthly return on 529 | B8: =(1+'1. Household Inputs'!B53)^(1/12)-1 -> 0.0048675506
A9: n_ret: Months to retirement | B9: ='1. Household Inputs'!B58 -> 252
A10: n_edu: Months to enrollment | B10: ='1. Household Inputs'!B59 -> 48
A11: PV_401k: Current 401(k) balance | B11: ='1. Household Inputs'!B20+'1. Household Inputs'!B21 -> 277000
A12: PMT_401k: Existing 401(k) monthly contrib | B12: ='1. Household Inputs'!C20+'1. Household Inputs'!C21 -> 1542
A13: PV_529: Current 529 balance | B13: ='1. Household Inputs'!B23 -> 22000
A14: PMT_529: Existing 529 monthly contrib | B14: ='1. Household Inputs'!C23 -> 200
A15: Target: College cost at enrollment | B15: ='1. Household Inputs'!B57 -> 140383.03
A16: BAL_auto: Auto loan balance | B16: ='1. Household Inputs'!B28 -> 18500
A17: r_auto: Auto loan monthly rate | B17: ='1. Household Inputs'!C28/12 -> 0.0049166667
A18: PMT_auto: Auto loan min payment | B18: ='1. Household Inputs'!D28 -> 373
A19: BAL_stud: Student loan balance | B19: ='1. Household Inputs'!B29 -> 31000
A20: r_stud: Student loan monthly rate | B20: ='1. Household Inputs'!C29/12 -> 0.00375
A21: PMT_stud: Student loan min payment | B21: ='1. Household Inputs'!D29 -> 290
A23: OBJECTIVE 3: Total Interest Paid on Debt (Minimize)
A24: Computed first because payoff months are needed by Objective 1. Mortgage interest is excluded from this objective. The mortgage minimum payment is reflected in the cash flow surplus calculation, but extra mortgage payments are not among the decision variables in this proof of concept, so mortgage interest is constant across all plans and does not affect relative efficiency.
A26: Component | B26: Plan A | C26: Plan B | D26: Notes
A27: Extra auto payment (monthly) | B27: ='2. Plan Comparison'!B9 -> 600 | C27: ='2. Plan Comparison'!B18 -> 100 | D27: Decision variable
A28: Total auto payment (min + extra) | B28: =B18+B27 -> 973 | C28: =B18+C27 -> 473 | D28: Freed amount post-payoff
A29: Auto payoff months (n_auto) | B29: =NPER(B17,-(B28),B16) -> 20.010684 | C29: =NPER(B17,-(C28),B16) -> 43.543789 | D29: NPER(rate, -pmt, bal)
A30: Auto total interest | B30: =B28*B29-B16 -> 970.39525 | C30: =C28*C29-B16 -> 2096.2123 | D30: Total paid - principal
A31: Extra student payment (monthly) | B31: ='2. Plan Comparison'!B10 -> 50 | C31: ='2. Plan Comparison'!B19 -> 100 | D31: Decision variable
A32: Total student payment (min + extra) | B32: =B21+B31 -> 340 | C32: =B21+C31 -> 390 | D32: Freed amount post-payoff
A33: Student payoff months (n_stud) | B33: =NPER(B20,-(B32),B19) -> 111.78675 | C33: =NPER(B20,-(C32),B19) -> 94.558577 | D33: NPER(rate, -pmt, bal)
A34: Student total interest | B34: =B32*B33-B19 -> 7007.494 | C34: =C32*C33-B19 -> 5877.8452 | D34: Total paid - principal
A35: OBJECTIVE 3: Total Interest Paid | B35: =B30+B34 -> 7977.8893 | C35: =C30+C34 -> 7974.0575 | D35: MINIMIZE
A37: OBJECTIVE 1: Retirement Balance at 65 — Phased Model (Maximize)
A38: FV = PV*(1+r)^n + base_stream + auto_redirect_stream + student_redirect_stream
A39: Each redirect stream starts when its debt is fully paid off.
A40: Redirect amount = full debt payment (min + extra), not just the extra.
A42: Component | B42: Plan A | C42: Plan B | D42: Notes
A43: Additional 401(k) from plan (monthly) | B43: ='2. Plan Comparison'!B12 -> 110.66667 | C43: ='2. Plan Comparison'!B21 -> 560.66667 | D43: Decision variable
A44: Base 401(k) stream (existing + x4) | B44: =B12+B43 -> 1652.6667 | C44: =B12+C43 -> 2102.6667 | D44: Flows for all 252 months
A45: FV of current 401(k) balance | B45: =B11*(1+B7)^B9 -> 1146935.8 | C45: =B11*(1+B7)^B9 -> 1146935.8 | D45: PV growth (same for both)
...

Sheet 4. Optimizer
A1: Pareto Frontier via Epsilon-Constraint Method
A2: This sheet finds the best possible outcomes across all three objectives simultaneously. Once filled, each row in the Pareto table below represents a different optimal trade-off: an allocation where no objective can be improved without worsening another.
A4: DECISION VARIABLES (Solver changes these)
A5: Allocation Bucket | B5: Monthly $ | C5: Lower Bound | D5: Upper Bound
A6: x1: Extra Auto Payment | B6: 712.22502 | C6: 0 | D6: ='1. Household Inputs'!B40 -> 1060.6667
A7: x2: Extra Student Payment | B7: 48.44165 | C7: 0 | D7: ='1. Household Inputs'!B40 -> 1060.6667
A8: x3: Additional 529 | B8: 300 | C8: 0 | D8: ='1. Household Inputs'!B40 -> 1060.6667
A9: x4: Additional 401(k) | B9: 0 | C9: 0 | D9: ='1. Household Inputs'!B40 -> 1060.6667
A10: Total Allocated | B10: =SUM(B6:B9) -> 1060.6667
A11: Budget Constraint (must = 0) | B11: ='1. Household Inputs'!B40-B10 -> 1.9122126e-10
A13: INTERMEDIATE COMPUTATIONS
A14: r_401k (monthly) | B14: ='3. Objective Functions'!B7 -> 0.0056541454
A15: r_529 (monthly) | B15: ='3. Objective Functions'!B8 -> 0.0048675506
A16: n_ret (months) | B16: ='3. Objective Functions'!B9 -> 252
A17: n_edu (months) | B17: ='3. Objective Functions'!B10 -> 48
A18: Total auto payment (min + x1) | B18: ='3. Objective Functions'!B18+B6 -> 1085.225
A19: Auto payoff months (n_auto) | B19: =NPER('3. Objective Functions'!B17,-(B18),'3. Objective Functions'!B16) -> 17.847903
A20: Total student payment (min + x2) | B20: ='3. Objective Functions'!B21+B7 -> 338.44165
A21: Student payoff months (n_stud) | B21: =NPER('3. Objective Functions'!B20,-(B20),'3. Objective Functions'!B19) -> 112.42665
A23: COMPUTED OBJECTIVES (phased model)
A24: Obj 1: Retirement Balance (phased) | B24: ='3. Objective Functions'!B11*(1+B14)^B16+('3. Objective Functions'!B12+B9)*(((1+B14)^B16-1)/B14)+B18*(((1+B14)^(B16-B19)-1)/B14)+B20*(((1+B14)^(B16-B21)-1)/B14) -> 2601762
A25: Obj 2: Education Funding Ratio | B25: =('3. Objective Functions'!B13*(1+B15)^B17+('3. Objective Functions'!B14+B8)*(((1+B15)^B17-1)/B15))/'3. Objective Functions'!B15 -> 0.38990759
A26: Obj 3: Total Interest Paid | B26: =B18*B19-'3. Objective Functions'!B16+B20*B21-'3. Objective Functions'!B19 -> 7918.851
A29: EPSILON CONSTRAINTS (set before each Solver run)
A30: Minimum Obj 2 (Funding Ratio >= this) | B30: 0 | C30: Constraint: B25 >= B30. Sets a floor: 'Find the best retirement outcome, but education funding must be at least this ratio.'
A31: Maximum Obj 3 (Total Interest <= this) | B31: 99999 | C31: Constraint: B26 <= B31. Sets a ceiling: 'Find the best retirement outcome, but total interest must not exceed this amount.'
A33: PARETO FRONTIER RESULTS TABLE
A34: Each row is the result of one Solver run with different constraint settings. Together, these points trace the efficient frontier. See Instructions for the sweep procedure.
J35: Epsilon Constraints
A36: Run # | B36: Obj 1: Retire $ | C36: Obj 2: Fund % | D36: Obj 3: Interest $ | E36: x1 (Auto) | F36: x2 (Student) | G36: x3 (529) | H36: x4 (401k) | I36: Obj Cell for Solver | J36: Min Obj 2 Value | K36: Max Obj 3 Value
A37: 1 | B37: 2771564.1 | C37: 0.2746718 | D37: 11447.252 | E37: 0 | F37: 0 | G37: 0 | H37: 1061 | I37: $B$24 (MAX) | J37: 0 | K37: 99999
A38: 2 | B38: 2182422.9 | C38: 0.6817102 | D38: 11447.252 | E38: 0 | F38: 0 | G38: 1061 | H38: 0 | I38: $B$25 (MAX) | J38: 0 | K38: 99999
A39: 3 | B39: 2760567.4 | C39: 0.2746718 | D39: 3333.5986 | E39: 331.52323 | F39: 729.14343 | G39: 0 | H39: 0 | I39: $B$26 (MIN) | J39: 0 | K39: 99999
A40: 4 | B40: 2617975.3 | C40: 0.376 | D40: 5362.0056 | E40: 590.07973 | F40: 206.79336 | G40: 263.79358 | H40: 0 | I40: $B$24 (MAX) | J40: 0.376 | K40: 5362.012
A41: 5 | B41: 2621145.2 | C41: 0.376 | D41: 7390 | E41: 728.03633 | F41: 68.836759 | G41: 263.79358 | H41: 0 | I41: $B$24 (MAX) | J41: 0.376 | K41: 7390.4254
A42: 6 | B42: 2623894.2 | C42: 0.376 | D42: 9419 | E42: 795.00247 | F42: 1.8706232 | G42: 263.79358 | H42: 0 | I42: $B$24 (MAX) | J42: 0.376 | K42: 9418.8388
A43: 7 | B43: 2469925.3 | C43: 0.478 | D43: 5362 | E43: 267.46929 | F43: 263.86129 | G43: 529.33609 | H43: 0 | I43: $B$24 (MAX) | J43: 0.478 | K43: 5362.012
A44: 8 | B44: 2473396.6 | C44: 0.478 | D44: 7390 | E44: 449.18672 | F44: 82.143853 | G44: 529.33609 | H44: 0 | I44: $B$24 (MAX) | J44: 0.478 | K44: 7390.4254
A45: 9 | B45: 2476227.6 | C45: 0.478 | D45: 9419 | E45: 523.24574 | F45: 8.0848339 | G45: 529.33609 | H45: 0 | I45: $B$24 (MAX) | J45: 0.478 | K45: 9418.8388
A46: 10 | B46: NA | I46: $B$24 (MAX) | J46: 0.58 | K46: 5362.012
...

Sheet 5. FOSH Signals
A1: FOSH Evaluative Signal Report
A2: Illustration of a FOSH output artifact. Signals computed from declared inputs.
A4: EFFICIENCY SIGNAL
A5: After completing the Pareto sweep, identify the nearest efficient point for each plan and enter its values below. See the Instructions sheet (Step 3) for how to identify the nearest efficient point.
A6: Metric | B6: Plan A | C6: Plan B | D6: Notes
A7: Plan Obj 1: Retirement Balance | B7: ='4. Optimizer'!B52 -> 2601762 | C7: ='4. Optimizer'!B53 -> 2600771.7 | D7: From Sheet 3
A8: Plan Obj 2: Funding Ratio | B8: ='4. Optimizer'!C52 -> 0.38990759 | C8: ='4. Optimizer'!C53 -> 0.38990759 | D8: From Sheet 3
A9: Plan Obj 3: Total Interest | B9: ='4. Optimizer'!D52 -> 7977.8893 | C9: ='4. Optimizer'!D53 -> 7974.0575 | D9: From Sheet 3
A11: Nearest Efficient Obj 1 | B11: ='4. Optimizer'!B59 -> 2601762 | C11: ='4. Optimizer'!B60 -> 2600771.7 | D11: Enter from Pareto table
A12: Nearest Efficient Obj 2 | B12: ='4. Optimizer'!C59 -> 0.38990759 | C12: ='4. Optimizer'!C60 -> 0.38990759 | D12: Enter from Pareto table
A13: Nearest Efficient Obj 3 | B13: ='4. Optimizer'!D59 -> 7918.851 | C13: ='4. Optimizer'!D60 -> 7226.2208 | D13: Enter from Pareto table
A15: Efficiency: Obj 1 (retire $) | B15: =IF(B11=0,"",B7/B11) -> 1 | C15: =IF(C11=0,"",C7/C11) -> 1 | D15: <100% = improvement available
A16: Efficiency: Obj 2 (fund %) | B16: =IF(B12=0,"",B8/B12) -> 1 | C16: =IF(C12=0,"",C8/C12) -> 1 | D16: <100% = improvement available
A17: Efficiency: Obj 3 (interest $) | B17: =IF(B9=0,"",B13/B9) -> 0.99259976 | C17: =IF(C9=0,"",C13/C9) -> 0.90621628 | D17: <100% = interest savings available
A19: Efficiency Signal | B19: =MIN(B15:B17) -> 0.99259976 | C19: =MIN(C15:C17) -> 0.90621628
A21: OBJECTIVE COVERAGE & EVALUABILITY SIGNAL
A22: Domain | B22: Status | C22: Evaluable? | D22: Notes
A23: Cashflow Sustainability | B23: Active | C23: Yes | D23: Declared; data sufficient
A24: Education Funding | B24: Active | C24: Yes | D24: Declared; data sufficient
A25: Debt Strategy | B25: Active | C25: Yes | D25: Declared; data sufficient
A26: Portfolio Efficiency | B26: Excluded | C26: N/A | D26: Intentionally excluded
A27: Emergency Liquidity | B27: Excluded | C27: N/A | D27: Intentionally excluded
A29: Coverage Signal | C29: =3/5 -> 0.6 | D29: 3 active domains of 5 total
A31: PROVENANCE & RELIABILITY SIGNAL
A32: Input Category | B32: Sourcing | C32: Commitment | D32: Notes
A33: Employment Income | B33: Document-backed | C33: Baseline | D33: Paystubs linked
A34: 401(k) Balances | B34: Document-backed | C34: Baseline | D34: Custodian statements
A35: 529 Balance | B35: Document-backed | C35: Baseline | D35: Custodian statement
A36: Debt Balances & Rates | B36: Document-backed | C36: Baseline | D36: Loan statements
A37: Monthly Expenses | B37: Household-reported | C37: Baseline | D37: NOT independently corroborated
A38: Home Equity | B38: Estimated | C38: Baseline | D38: Zillow; not appraised
A39: Extra 529 Contribution | B39: N/A | C39: Approved | D39: Household has agreed
A40: Extra Debt Payments | B40: N/A | C40: Proposed | D40: NOT yet committed
A41: Extra 401(k) Contribution | B41: N/A | C41: Proposed | D41: NOT yet committed
A43: STRUCTURAL VALIDITY SIGNAL
A44: Check | B44: Plan A | C44: Plan B | D44: Notes
A45: Budget fully allocated? | B45: =IF('2. Plan Comparison'!B14=0,"PASS","FAIL") -> PASS | C45: =IF('2. Plan Comparison'!B23=0,"PASS","FAIL") -> PASS | D45: Surplus = 0
A46: All allocations >= 0? | B46: =IF(AND('2. Plan Comparison'!B9>=0,'2. Plan Comparison'!B10>=0,'2. Plan Comparison'!B11>=0,'2. Plan Comparison'!B12>=0),"PASS","FAIL") -> PASS | C46: =IF(AND('2. Plan Comparison'!B18>=0,'2. Plan Comparison'!B19>=0,'2. Plan Comparison'!B20>=0,'2. Plan Comparison'!B21>=0),"PASS","FAIL") -> PASS | D46: Non-negativity
A47: 401(k) within annual limit? | B47: PASS | C47: PASS | D47: Simplified check
A48: 529 within exclusion? | B48: PASS | C48: PASS | D48: Simplified check
...

Sheet 6. Instructions
A1: FOSH PROOF OF CONCEPT: INSTRUCTIONS
A2: This workbook demonstrates FOSH's evaluative architecture using Excel Solver. All results are deterministic and fully reproducible given declared inputs and reference assumptions.
A4: WORKBOOK STRUCTURE
A5: Sheet 1 (Household Inputs): Declares all household facts, modeling scope, and reference assumptions. Nothing on this sheet differs between the two plans.
A6: Sheet 2 (Plan Comparison): Defines two competing plans as specific surplus allocations. Blue-text cells are the plan's recommended monthly dollar amounts.
A7: Sheet 3 (Objective Functions): Computes three declared objectives for each plan using identical formulas: retirement balance at 65, education funding ratio at enrollment, and total interest paid on debt.
A8: Sheet 4 (Optimizer): Solver-ready layout for tracing the Pareto efficient frontier. Yellow cells are decision variables that Solver changes.
A9: Sheet 5 (FOSH Signals): The evaluative output. Signals across FOSH's reporting dimensions, computed from declared inputs and frontier results.
A11: PREREQUISITES: ENABLING AND CONFIGURING SOLVER
A12: Excel Solver is required but may not be visible by default. To enable it:
A13: 1. Go to File > Options > Add-ins.
A14: 2. At the bottom, next to 'Manage,' select 'Excel Add-ins' and click Go.
... A121: Results differ slightly from the paper's Table 2: Small differences may arise from Solver precision settings or starting points. Results should be directionally identical and numerically very close.
